<robot
  name="JACO3_URDF_V11" version="1.0">
  <link
    name="base_link">
    <inertial>
      <origin
        xyz="-0.000648 -0.000166 0.084487"
        rpy="0 0 0" />
      <mass
        value="1.697353" />
      <inertia
        ixx="0.004622"
        ixy="9E-06"
        ixz="6E-05"
        iyy="0.004495"
        iyz="9E-06"
        izz="0.002079" />
    </inertial>
    <visual>
      <origin
        xyz="0 0 0"
        rpy="0 0 0" />
      <geometry>
        <mesh
          filename="package://kortex_description/meshes/base_link.STL" />
      </geometry>
      <material
        name="">
        <color
          rgba="0.79216 0.81961 0.93333 1" />
      </material>
    </visual>
    <collision>
      <origin
        xyz="0 0 0"
        rpy="0 0 0" />
      <geometry>
        <mesh
          filename="package://kortex_description/meshes/base_link.STL" />
      </geometry>
    </collision>
  </link>
  <link
    name="Shoulder_Link">
    <inertial>
      <origin
        xyz="-2.3E-05 -0.010364 -0.07336"
        rpy="0 0 0" />
      <mass
        value="1.377353" />
      <inertia
        ixx="0.00457"
        ixy="1E-06"
        ixz="2E-06"
        iyy="0.004831"
        iyz="0.000448"
        izz="0.001409" />
    </inertial>
    <visual>
      <origin
        xyz="0 0 0"
        rpy="0 0 0" />
      <geometry>
        <mesh
          filename="package://kortex_description/meshes/Shoulder_Link.STL" />
      </geometry>
      <material
        name="">
        <color
          rgba="0.75294 0.75294 0.75294 1" />
      </material>
    </visual>
    <collision>
      <origin
        xyz="0 0 0"
        rpy="0 0 0" />
      <geometry>
        <mesh
          filename="package://kortex_description/meshes/Shoulder_Link.STL" />
      </geometry>
    </collision>
  </link>
  <joint
    name="Actuator1"
    type="continuous">
    <origin
      xyz="6.1995E-05 0 0.15643"
      rpy="-3.1416 3.2891E-18 1.9637E-50" />
    <parent
      link="base_link" />
    <child
      link="Shoulder_Link" />
    <axis
      xyz="0 0 1" />
    <limit
      effort="39"
      velocity="0.8727" />
  </joint>
  <link
    name="HalfArm1_Link">
    <inertial>
      <origin
        xyz="-4.4E-05 -0.09958 -0.013278"
        rpy="0 0 0" />
      <mass
        value="1.163667" />
      <inertia
        ixx="0.011088"
        ixy="5E-06"
        ixz="0"
        iyy="0.001072"
        iyz="-0.000691"
        izz="0.011255" />
    </inertial>
    <visual>
      <origin
        xyz="0 0 0"
        rpy="0 0 0" />
      <geometry>
        <mesh
          filename="package://kortex_description/meshes/HalfArm1_Link.STL" />
      </geometry>
      <material
        name="">
        <color
          rgba="0.75294 0.75294 0.75294 1" />
      </material>
    </visual>
    <collision>
      <origin
        xyz="0 0 0"
        rpy="0 0 0" />
      <geometry>
        <mesh
          filename="package://kortex_description/meshes/HalfArm1_Link.STL" />
      </geometry>
    </collision>
  </link>
  <joint
    name="Actuator2"
    type="revolute">
    <origin
      xyz="0 0.005375 -0.12838"
      rpy="1.5708 2.4106E-17 3.1919E-16" />
    <parent
      link="Shoulder_Link" />
    <child
      link="HalfArm1_Link" />
    <axis
      xyz="0 0 1" />
    <limit
      lower="-2.2"
      upper="2.2"
      effort="39"
      velocity="0.8727" />
  </joint>
  <link
    name="HalfArm2_Link">
    <inertial>
      <origin
        xyz="-4.4E-05 -0.006641 -0.117892"
        rpy="0 0 0" />
      <mass
        value="1.16366" />
      <inertia
        ixx="0.010932"
        ixy="0"
        ixz="-7E-06"
        iyy="0.011127"
        iyz="0.000606"
        izz="0.001043" />
    </inertial>
    <visual>
      <origin
        xyz="0 0 0"
        rpy="0 0 0" />
      <geometry>
        <mesh
          filename="package://kortex_description/meshes/HalfArm2_Link.STL" />
      </geometry>
      <material
        name="">
        <color
          rgba="0.75294 0.75294 0.75294 1" />
      </material>
    </visual>
    <collision>
      <origin
        xyz="0 0 0"
        rpy="0 0 0" />
      <geometry>
        <mesh
          filename="package://kortex_description/meshes/HalfArm2_Link.STL" />
      </geometry>
    </collision>
  </link>
  <joint
    name="Actuator3"
    type="continuous">
    <origin
      xyz="0 -0.21038 -0.006375"
      rpy="-1.5708 9.8608E-32 -2.7983E-16" />
    <parent
      link="HalfArm1_Link" />
    <child
      link="HalfArm2_Link" />
    <axis
      xyz="0 0 1" />
    <limit
      effort="39"
      velocity="0.8727" />
  </joint>
  <link
    name="ForeArm_Link">
    <inertial>
      <origin
        xyz="-1.8E-05 -0.075478 -0.015006"
        rpy="0 0 0" />
      <mass
        value="0.930287" />
      <inertia
        ixx="0.008147"
        ixy="-1E-06"
        ixz="0"
        iyy="0.000631"
        iyz="-0.0005"
        izz="0.008316" />
    </inertial>
    <visual>
      <origin
        xyz="0 0 0"
        rpy="0 0 0" />
      <geometry>
        <mesh
          filename="package://kortex_description/meshes/ForeArm_Link.STL" />
      </geometry>
      <material
        name="">
        <color
          rgba="0.75294 0.75294 0.75294 1" />
      </material>
    </visual>
    <collision>
      <origin
        xyz="0 0 0"
        rpy="0 0 0" />
      <geometry>
        <mesh
          filename="package://kortex_description/meshes/ForeArm_Link.STL" />
      </geometry>
    </collision>
  </link>
  <joint
    name="Actuator4"
    type="revolute">
    <origin
      xyz="0 0.006375 -0.21038"
      rpy="1.5708 3.0688E-17 -6.9389E-18" />
    <parent
      link="HalfArm2_Link" />
    <child
      link="ForeArm_Link" />
    <axis
      xyz="0 0 1" />
    <limit
      lower="-2.5656"
      upper="2.5656"
      effort="39"
      velocity="0.8727" />
  </joint>
  <link
    name="SphericalWrist1_Link">
    <inertial>
      <origin
        xyz="1E-06 -0.009432 -0.063883"
        rpy="0 0 0" />
      <mass
        value="0.678106" />
      <inertia
        ixx="0.001596"
        ixy="0"
        ixz="0"
        iyy="0.001607"
        iyz="0.000256"
        izz="0.000399" />
    </inertial>
    <visual>
      <origin
        xyz="0 0 0"
        rpy="0 0 0" />
      <geometry>
        <mesh
          filename="package://kortex_description/meshes/SphericalWrist1_Link.STL" />
      </geometry>
      <material
        name="">
        <color
          rgba="0.75294 0.75294 0.75294 1" />
      </material>
    </visual>
    <collision>
      <origin
        xyz="0 0 0"
        rpy="0 0 0" />
      <geometry>
        <mesh
          filename="package://kortex_description/meshes/SphericalWrist1_Link.STL" />
      </geometry>
    </collision>
  </link>
  <joint
    name="Actuator5"
    type="continuous">
    <origin
      xyz="0 -0.20843 -0.006375"
      rpy="-1.5708 1.497E-17 7.6501E-17" />
    <parent
      link="ForeArm_Link" />
    <child
      link="SphericalWrist1_Link" />
    <axis
      xyz="0 0 1" />
    <limit
      effort="9"
      velocity="0.8727" />
  </joint>
  <link
    name="SphericalWrist2_Link">
    <inertial>
      <origin
        xyz="1E-06 -0.045483 -0.00965"
        rpy="0 0 0" />
      <mass
        value="0.678106" />
      <inertia
        ixx="0.001641"
        ixy="0"
        ixz="0"
        iyy="0.00041"
        iyz="-0.000278"
        izz="0.001641" />
    </inertial>
    <visual>
      <origin
        xyz="0 0 0"
        rpy="0 0 0" />
      <geometry>
        <mesh
          filename="package://kortex_description/meshes/SphericalWrist2_Link.STL" />
      </geometry>
      <material
        name="">
        <color
          rgba="0.75294 0.75294 0.75294 1" />
      </material>
    </visual>
    <collision>
      <origin
        xyz="0 0 0"
        rpy="0 0 0" />
      <geometry>
        <mesh
          filename="package://kortex_description/meshes/SphericalWrist2_Link.STL" />
      </geometry>
    </collision>
  </link>
  <joint
    name="Actuator6"
    type="revolute">
    <origin
      xyz="0 0.00017505 -0.10593"
      rpy="1.5708 3.3255E-17 -8.0962E-15" />
    <parent
      link="SphericalWrist1_Link" />
    <child
      link="SphericalWrist2_Link" />
    <axis
      xyz="0 0 1" />
    <limit
      lower="-2.05"
      upper="2.05"
      effort="9"
      velocity="0.8727" />
  </joint>
  <link
    name="Bracelet_Link">
    <inertial>
      <origin
        xyz="-0.000281 -0.011402 -0.03108"
        rpy="0 0 0" />
      <mass
        value="0.500657" />
      <inertia
        ixx="0.00057"
        ixy="2E-06"
        ixz="3E-06"
        iyy="0.000352"
        iyz="0.000111"
        izz="0.000609" />
    </inertial>
    <visual>
      <origin
        xyz="0 0 0"
        rpy="0 0 0" />
      <geometry>
        <mesh
          filename="package://kortex_description/meshes/Bracelet_Link.STL" />
      </geometry>
      <material
        name="">
        <color
          rgba="0.75294 0.75294 0.75294 1" />
      </material>
    </visual>
    <collision>
      <origin
        xyz="0 0 0"
        rpy="0 0 0" />
      <geometry>
        <mesh
          filename="package://kortex_description/meshes/Bracelet_Link.STL" />
      </geometry>
    </collision>
  </link>
  <joint
    name="Actuator7"
    type="continuous">
    <origin
      xyz="0 -0.10593 -0.00017505"
      rpy="-1.5708 -2.3419E-17 1.52E-17" />
    <parent
      link="SphericalWrist2_Link" />
    <child
      link="Bracelet_Link" />
    <axis
      xyz="0 0 1" />
    <limit
      effort="9"
      velocity="0.8727" />
  </joint>
  <link
    name="EndEffector_Link">
    <inertial>
      <origin
        xyz="0 0 0"
        rpy="0 0 0" />
      <mass
        value="0" />
      <inertia
        ixx="0"
        ixy="0"
        ixz="0"
        iyy="0"
        iyz="0"
        izz="0" />
    </inertial>
    <visual>
      <origin
        xyz="0 0 0"
        rpy="0 0 0" />
      <geometry>
        <mesh
          filename="package://kortex_description/meshes/EndEffector_Link.STL" />
      </geometry>
      <material
        name="">
        <color
          rgba="0.79216 0.81961 0.93333 1" />
      </material>
    </visual>
    <collision>
      <origin
        xyz="0 0 0"
        rpy="0 0 0" />
      <geometry>
        <mesh
          filename="package://kortex_description/meshes/EndEffector_Link.STL" />
      </geometry>
    </collision>
  </link>
  <joint
    name="EndEffector"
    type="fixed">
    <origin
      xyz="0 0 -0.061525"
      rpy="3.1416 1.0815E-32 0" />
    <parent
      link="Bracelet_Link" />
    <child
      link="EndEffector_Link" />
    <axis
      xyz="0 0 0" />
  </joint>
</robot>
